Workbook

Sheet Resumo
A1: fatura | B1: ord | C1: item | D1: valor
A2: 269308 | B2: 1 | C2: LEVA 1
A3: 269308 | B3: 2 | C3: (+) Notas fiscais recolhidas | D3: 414653.70
A4: 269308 | B4: 3 | C4: (-) Créditos de estorno | D4: -1468.57
A5: 269308 | B5: 4 | C5: (=) Pagamento no vencimento | D5: 413185.13
A6: 269308 | B6: 5 | C6: LEVA 2
A7: 269308 | B7: 6 | C7: (+) Abastecimento cancelado | D7: 331.89
A8: 269308 | B8: 7 | C8: (+) Sem nota fiscal | D8: 29660.05
A9: 269308 | B9: 8 | C9: (=) Saldo a pagar | D9: 29991.94
A10: 269308 | B10: 9 | C10: TOTAL DA FATURA (conferência) | D10: 443177.07

Sheet Contabilidade
A1: cnpj_cliente | B1: garagem | C1: matricula_veiculo | D1: placa | E1: natureza_bluefllet | F1: fatura_atual | G1: data_transacao | H1: id_transacao_atual | I1: numero_nota_fiscal | J1: nome_posto | K1: cnpj_posto | L1: cnpj_filial_nfe | M1: valor_item_liquido | N1: tipo_lancamento | O1: id_referencia_original | P1: fatura_origem_referencia | Q1: data_original_referencia | R1: valor_cobrado_na_epoca | S1: status_fiscal | T1: nfe_tipo_operacao | U1: nfe_data_emissao | V1: nfe_valor_nota | W1: chave_nfe | X1: categoria_relatorio | Y1: titulo_data_geracao | Z1: titulo_data_vencimento | AA1: titulo_valor_total | AB1: fatura_credito_retorno | AC1: data_credito_retorno | AD1: tem_credito_gerado | AE1: chave_nfe_texto
A2: 90739624000118 | B2: GRITSCH - CGB | D2: SFL2F19 | E2: COMBUSTÍVEL | F2: 269308 | G2: 2026-08-01 14:03:55.000 -0300 | H2: 25041264 | J2: POSTO SAO JOSE 1 | K2: 4903852000140 | M2: -285.67 | N2: ESTORNO (CRÉDITO) | O2: 24567446 | P2: 267384 | Q2: 2026-08-01 14:03:55.000 -0300 | R2: 285.67 | S2: CRÉDITO / ESTORNO | X2: 4. Crédito de estorno (desconto) | Y2: 2026-08-15 00:00:00.000 -0300 | Z2: 2026-08-26 00:00:00.000 -0300 | AA2: 443177.07 | AD2: false
A3: 90739624000118 | B3: GRITSCH - POA | D3: UBR9A92 | E3: COMBUSTÍVEL | F3: 269308 | G3: 2026-07-28 18:26:06.000 -0300 | H3: 25041210 | J3: SIM REDE - ALEGRETE - 019877 - CENTRO RS | K3: 7473735019877 | M3: -251.86 | N3: ESTORNO (CRÉDITO) | O3: 24375893 | P3: 267384 | Q3: 2026-07-28 18:26:06.000 -0300 | R3: 251.86 | S3: CRÉDITO / ESTORNO | X3: 4. Crédito de estorno (desconto) | Y3: 2026-08-15 00:00:00.000 -0300 | Z3: 2026-08-26 00:00:00.000 -0300 | AA3: 443177.07 | AD3: false
A4: 90739624000118 | B4: GRITSCH - PET | D4: UBN9E24 | E4: COMBUSTÍVEL | F4: 269308 | G4: 2026-07-31 08:16:17.000 -0300 | H4: 25030298 | J4: SIM REDE - PELOTAS FERNANDO OSORIO 0093-08 - CENTRO RS | K4: 7473735009308 | M4: -141.68 | N4: ESTORNO (CRÉDITO) | O4: 24502758 | P4: 267384 | Q4: 2026-07-31 08:16:17.000 -0300 | R4: 141.68 | S4: CRÉDITO / ESTORNO | X4: 4. Crédito de estorno (desconto) | Y4: 2026-08-15 00:00:00.000 -0300 | Z4: 2026-08-26 00:00:00.000 -0300 | AA4: 443177.07 | AD4: false
A5: 90739624000118 | B5: GRITSCH - RVD | C5: 22475 | D5: SDU9F98 | E5: COMBUSTÍVEL | F5: 269308 | G5: 2026-08-07 10:14:51.000 -0300 | H5: 24861044 | J5: POSTO ALDO JATAI INDUSTRIAL - REDE ALDO | K5: 2651099000117 | M5: -331.89 | N5: ESTORNO (CRÉDITO) | O5: 24860705 | P5: 269308 | Q5: 2026-08-07 10:14:51.000 -0300 | R5: 331.89 | S5: CRÉDITO / ESTORNO | X5: 4. Crédito de estorno (desconto) | Y5: 2026-08-15 00:00:00.000 -0300 | Z5: 2026-08-26 00:00:00.000 -0300 | AA5: 443177.07 | AD5: false
A6: 90739624000118 | B6: GRITSCH - GOI | D6: TBE5I66 | E6: COMBUSTÍVEL | F6: 269308 | G6: 2026-08-03 14:18:13.000 -0300 | H6: 25027473 | J6: POSTO SAO JUDAS TADEU - REDE Z+Z (RODOVIA) | K6: 13759928000104 | M6: -231.7 | N6: ESTORNO (CRÉDITO) | O6: 24661956 | P6: 267384 | Q6: 2026-08-03 14:18:13.000 -0300 | R6: 231.70 | S6: CRÉDITO / ESTORNO | X6: 4. Crédito de estorno (desconto) | Y6: 2026-08-15 00:00:00.000 -0300 | Z6: 2026-08-26 00:00:00.000 -0300 | AA6: 443177.07 | AD6: false
A7: 90739624000118 | B7: GRITSCH - GOI | D7: TBE5I66 | E7: COMBUSTÍVEL | F7: 269308 | G7: 2026-07-30 15:13:04.000 -0300 | H7: 25029954 | J7: POSTO SAO JUDAS TADEU - REDE Z+Z (RODOVIA) | K7: 13759928000104 | M7: -225.77 | N7: ESTORNO (CRÉDITO) | O7: 24469630 | P7: 267384 | Q7: 2026-07-30 15:13:04.000 -0300 | R7: 225.77 | S7: CRÉDITO / ESTORNO | X7: 4. Crédito de estorno (desconto) | Y7: 2026-08-15 00:00:00.000 -0300 | Z7: 2026-08-26 00:00:00.000 -0300 | AA7: 443177.07 | AD7: false
A8: 90739624000118 | B8: GRITSCH - MATRIZ | D8: SFH7D75 | E8: COMBUSTÍVEL | F8: 269308 | G8: 2026-08-11 20:32:34.000 -0300 | H8: 25063040 | I8: 29106 | J8: POSTO 2 IRMAOS | K8: 76493295000147 | L8: 9576274000106 | M8: 252.02 | N8: ABASTECIMENTO (DÉBITO) | S8: NFE VINCULADA | T8: I | U8: 2026-08-10 21:00:00.000 -0300 | V8: 252.02 | W8: 4.1260876e+43 | X8: 1. Com nota fiscal recolhida | Y8: 2026-08-15 00:00:00.000 -0300 | Z8: 2026-08-26 00:00:00.000 -0300 | AA8: 443177.07 | AD8: false | AE8: '41260876493295000147550020000291061002782187
A9: 90739624000118 | B9: GRITSCH - RVD | D9: TBK1J24 | E9: COMBUSTÍVEL | F9: 269308 | G9: 2026-08-11 20:16:50.000 -0300 | H9: 25062781 | I9: 5325 | J9: REDE MONTE CARLO - POSTO SAO JOSE | K9: 42733072000198 | L9: 90739624000380 | M9: 283.6 | N9: ABASTECIMENTO (DÉBITO) | S9: NFE VINCULADA | T9: I | U9: 2026-08-11 21:00:00.000 -0300 | V9: 283.60 | W9: 3.5260843e+43 | X9: 1. Com nota fiscal recolhida | Y9: 2026-08-15 00:00:00.000 -0300 | Z9: 2026-08-26 00:00:00.000 -0300 | AA9: 443177.07 | AD9: false | AE9: '35260842733072000198550080000053251524484620
A10: 90739624000118 | B10: GRITSCH - GOI | D10: UAV5J73 | E10: COMBUSTÍVEL | F10: 269308 | G10: 2026-08-11 19:42:40.000 -0300 | H10: 25062357 | I10: 38315 | J10: AUTO POSTO CIDADE - PORANGATU | K10: 33360405000190 | L10: 90739624001947 | M10: 220.77 | N10: ABASTECIMENTO (DÉBITO) | S10: NFE VINCULADA | T10: I | U10: 2026-08-10 21:00:00.000 -0300 | V10: 220.77 | W10: 5.2260833e+43 | X10: 1. Com nota fiscal recolhida | Y10: 2026-08-15 00:00:00.000 -0300 | Z10: 2026-08-26 00:00:00.000 -0300 | AA10: 443177.07 | AD10: false | AE10: '52260833360405000190550020000383151008888133
A11: 90739624000118 | B11: GRITSCH - SAO (PERUS) | D11: UCB6D90 | E11: COMBUSTÍVEL | F11: 269308 | G11: 2026-08-11 19:17:08.000 -0300 | H11: 25061999 | I11: 1052949 | J11: POSTO DO TREVO - REDE GRAAL | K11: 55973291000196 | L11: 90739624000380 | M11: 336.5 | N11: ABASTECIMENTO (DÉBITO) | S11: NFE VINCULADA | T11: I | U11: 2026-08-10 21:00:00.000 -0300 | V11: 336.50 | W11: 3.5260856e+43 | X11: 1. Com nota fiscal recolhida | Y11: 2026-08-15 00:00:00.000 -0300 | Z11: 2026-08-26 00:00:00.000 -0300 | AA11: 443177.07 | AD11: false | AE11: '35260855973291000196550030010529491018448930
A12: 90739624000118 | B12: GRITSCH - CWB (BASE) | D12: UCC8A40 | E12: COMBUSTÍVEL | F12: 269308 | G12: 2026-08-11 19:14:36.000 -0300 | H12: 25061890 | I12: 820855 | J12: GP POSTOS - POSTO SAO JOSE | K12: 79964177000591 | L12: 9576274000106 | M12: 698.82 | N12: ABASTECIMENTO (DÉBITO) | S12: NFE VINCULADA | T12: I | U12: 2026-08-10 21:00:00.000 -0300 | V12: 698.82 | W12: 4.126088e+43 | X12: 1. Com nota fiscal recolhida | Y12: 2026-08-15 00:00:00.000 -0300 | Z12: 2026-08-26 00:00:00.000 -0300 | AA12: 443177.07 | AD12: false | AE12: '41260879964177000591550020008208551011758525
A13: 90739624000118 | B13: GRITSCH - PMW | D13: UAV5J75 | E13: COMBUSTÍVEL | F13: 269308 | G13: 2026-08-11 19:09:13.000 -0300 | H13: 25061863 | I13: 38314 | J13: AUTO POSTO CIDADE - PORANGATU | K13: 33360405000190 | L13: 90739624001947 | M13: 196.89 | N13: ABASTECIMENTO (DÉBITO) | S13: NFE VINCULADA | T13: I | U13: 2026-08-10 21:00:00.000 -0300 | V13: 196.89 | W13: 5.2260833e+43 | X13: 1. Com nota fiscal recolhida | Y13: 2026-08-15 00:00:00.000 -0300 | Z13: 2026-08-26 00:00:00.000 -0300 | AA13: 443177.07 | AD13: false | AE13: '52260833360405000190550020000383141008887997
A14: 90739624000118 | B14: GRITSCH - CWB (BASE) | C14: 15984 | D14: BBW0C96 | E14: COMBUSTÍVEL | F14: 269308 | G14: 2026-08-11 18:36:53.000 -0300 | H14: 25061415 | I14: 820852 | J14: GP POSTOS - POSTO SAO JOSE | K14: 79964177000591 | L14: 9576274000106 | M14: 1878.84 | N14: ABASTECIMENTO (DÉBITO) | S14: NFE VINCULADA | T14: I | U14: 2026-08-10 21:00:00.000 -0300 | V14: 1878.84 | W14: 4.126088e+43 | X14: 1. Com nota fiscal recolhida | Y14: 2026-08-15 00:00:00.000 -0300 | Z14: 2026-08-26 00:00:00.000 -0300 | AA14: 443177.07 | AD14: false | AE14: '41260879964177000591550020008208521011758434
A15: 90739624000118 | B15: GRITSCH - CHA | D15: RHT0B69 | E15: COMBUSTÍVEL | F15: 269308 | G15: 2026-08-11 18:33:59.000 -0300 | H15: 25061399 | I15: 4439 | J15: BUFFON 74 | K15: 93489243007471 | L15: 90739624002323 | M15: 475.6 | N15: ABASTECIMENTO (DÉBITO) | S15: NFE VINCULADA | T15: I | U15: 2026-08-10 21:00:00.000 -0300 | V15: 475.60 | W15: 4.3260893e+43 | X15: 1. Com nota fiscal recolhida | Y15: 2026-08-15 00:00:00.000 -0300 | Z15: 2026-08-26 00:00:00.000 -0300 | AA15: 443177.07 | AD15: false | AE15: '43260893489243007471550080000044391522201280
A16: 90739624000118 | B16: GRITSCH - GOI | D16: TBE5I62 | E16: COMBUSTÍVEL | F16: 269308 | G16: 2026-08-11 17:34:10.000 -0300 | H16: 25056047 | I16: 81440 | J16: POSTO 10 GOIANIA | REDE CARRETEIRO | K16: 1272434001002 | L16: 90739624001947 | M16: 260.28 | N16: ABASTECIMENTO (DÉBITO) | S16: NFE VINCULADA | T16: I | U16: 2026-08-10 21:00:00.000 -0300 | V16: 260.28 | W16: 5.2260801e+43 | X16: 1. Com nota fiscal recolhida | Y16: 2026-08-15 00:00:00.000 -0300 | Z16: 2026-08-26 00:00:00.000 -0300 | AA16: 443177.07 | AD16: false | AE16: '52260801272434001002550020000814401274796734
A17: 90739624000118 | B17: GRITSCH - SAO (PERUS) | C17: 26123 | D17: TAS4H20 | E17: COMBUSTÍVEL | F17: 269308 | G17: 2026-08-11 17:25:18.000 -0300 | H17: 25055879 | I17: 374251 | J17: AUTO POSTO LIMOEIRO - PALOMA - REDE GRAAL | K17: 5065447000162 | L17: 90739624000380 | M17: 221.63 | N17: ABASTECIMENTO (DÉBITO) | S17: NFE VINCULADA | T17: I | U17: 2026-08-10 21:00:00.000 -0300 | V17: 221.63 | W17: 3.5260805e+43 | X17: 1. Com nota fiscal recolhida | Y17: 2026-08-15 00:00:00.000 -0300 | Z17: 2026-08-26 00:00:00.000 -0300 | AA17: 443177.07 | AD17: false | AE17: '35260805065447000162550060003742511006200254
A18: 90739624000118 | B18: GRITSCH - RDN | C18: 23395 | D18: SEI5B85 | E18: COMBUSTÍVEL | F18: 269308 | G18: 2026-08-11 17:22:05.000 -0300 | H18: 25055759 | I18: 10286 | J18: REDE DINO - POSTO SERRA DAS ARARAS | K18: 50128357000551 | L18: 90739624001866 | M18: 189.65 | N18: ABASTECIMENTO (DÉBITO) | S18: NFE VINCULADA | T18: I | U18: 2026-08-10 21:00:00.000 -0300 | V18: 189.64 | W18: 5.126085e+43 | X18: 1. Com nota fiscal recolhida | Y18: 2026-08-15 00:00:00.000 -0300 | Z18: 2026-08-26 00:00:00.000 -0300 | AA18: 443177.07 | AD18: false | AE18: '51260850128357000551550050000102861001035117
A19: 90739624000118 | B19: GRITSCH - POA | D19: TAI9A24 | E19: COMBUSTÍVEL | F19: 269308 | G19: 2026-08-11 17:17:58.000 -0300 | H19: 25055716 | I19: 58070 | J19: SIM REDE - ALEGRETE - 019877 - CENTRO RS | K19: 7473735019877 | L19: 90739624002323 | M19: 255.16 | N19: ABASTECIMENTO (DÉBITO) | S19: NFE VINCULADA | T19: I | U19: 2026-08-10 21:00:00.000 -0300 | V19: 255.16 | W19: 4.3260807e+43 | X19: 1. Com nota fiscal recolhida | Y19: 2026-08-15 00:00:00.000 -0300 | Z19: 2026-08-26 00:00:00.000 -0300 | AA19: 443177.07 | AD19: false | AE19: '43260807473735019877550080000580701009183062
A20: 90739624000118 | B20: GRITSCH - CWB (BASE) | D20: SFM3H28 | E20: COMBUSTÍVEL | F20: 269308 | G20: 2026-08-11 17:13:35.000 -0300 | H20: 25055585 | I20: 29103 | J20: POSTO 2 IRMAOS | K20: 76493295000147 | L20: 9576274000106 | M20: 620.71 | N20: ABASTECIMENTO (DÉBITO) | S20: NFE VINCULADA | T20: I | U20: 2026-08-10 21:00:00.000 -0300 | V20: 620.71 | W20: 4.1260876e+43 | X20: 1. Com nota fiscal recolhida | Y20: 2026-08-15 00:00:00.000 -0300 | Z20: 2026-08-26 00:00:00.000 -0300 | AA20: 443177.07 | AD20: false | AE20: '41260876493295000147550020000291031002781545
A21: 90739624000118 | B21: GRITSCH - GOI | D21: TBQ1G08 | E21: ARLA | F21: 269308 | G21: 2026-08-11 17:12:26.000 -0300 | H21: 25055573 | I21: 90596 | J21: POSTO 6 RIANAPOLIS | REDE CARRETEIRO | K21: 1272434000618 | L21: 90739624001947 | M21: 59.8 | N21: ABASTECIMENTO (DÉBITO) | S21: NFE VINCULADA | T21: I | U21: 2026-08-10 21:00:00.000 -0300 | V21: 59.80 | W21: 5.2260801e+43 | X21: 1. Com nota fiscal recolhida | Y21: 2026-08-15 00:00:00.000 -0300 | Z21: 2026-08-26 00:00:00.000 -0300 | AA21: 443177.07 | AD21: false | AE21: '52260801272434000618550030000905961193214770
A22: 90739624000118 | B22: GRITSCH - CSC | D22: SES0D47 | E22: COMBUSTÍVEL | F22: 269308 | G22: 2026-08-11 17:09:49.000 -0300 | H22: 25055555 | I22: 163227 | J22: POSTO NOVO FOXX - REDE ESTRADA | K22: 2763612000161 | L22: 90739624003133 | M22: 660.15 | N22: ABASTECIMENTO (DÉBITO) | S22: NFE VINCULADA | T22: I | U22: 2026-08-10 21:00:00.000 -0300 | V22: 660.15 | W22: 4.1260803e+43 | X22: 1. Com nota fiscal recolhida | Y22: 2026-08-15 00:00:00.000 -0300 | Z22: 2026-08-26 00:00:00.000 -0300 | AA22: 443177.07 | AD22: false | AE22: '41260802763612000161550020001632271664883173
A23: 90739624000118 | B23: GRITSCH - PMW | D23: TAR2F19 | E23: COMBUSTÍVEL | F23: 269308 | G23: 2026-08-11 17:05:49.000 -0300 | H23: 25055420 | I23: 99280 | J23: RODOPOSTO | K23: 4219621000111 | L23: 90739624000118 | M23: 305.06 | N23: ABASTECIMENTO (DÉBITO) | S23: NFE VINCULADA | T23: I | U23: 2026-08-11 21:00:00.000 -0300 | V23: 305.06 | W23: 1.7260804e+43 | X23: 1. Com nota fiscal recolhida | Y23: 2026-08-15 00:00:00.000 -0300 | Z23: 2026-08-26 00:00:00.000 -0300 | AA23: 443177.07 | AD23: false | AE23: '17260804219621000111550010000992801351423972
A24: 90739624000118 | B24: GRITSCH - CTB | C24: 24753 | D24: SFI4A35 | E24: COMBUSTÍVEL | F24: 269308 | G24: 2026-08-11 16:59:05.000 -0300 | H24: 25055367 | I24: 168726 | J24: POSTO CAPITAL | K24: 82156977000248 | L24: 90739624001432 | M24: 234.43 | N24: ABASTECIMENTO (DÉBITO) | S24: NFE VINCULADA | T24: I | U24: 2026-08-10 21:00:00.000 -0300 | V24: 234.43 | W24: 4.2260882e+43 | X24: 1. Com nota fiscal recolhida | Y24: 2026-08-15 00:00:00.000 -0300 | Z24: 2026-08-26 00:00:00.000 -0300 | AA24: 443177.07 | AD24: false | AE24: '42260882156977000248550010001687261220982295
A25: 90739624000118 | B25: GRITSCH - CGB | D25: SFL2F19 | E25: COMBUSTÍVEL | F25: 269308 | G25: 2026-08-11 16:50:56.000 -0300 | H25: 25055190 | I25: 171981 | J25: POSTO JK - COMODORO | REDE AMERICA | K25: 22611652000103 | L25: 90739624001866 | M25: 139.9 | N25: ABASTECIMENTO (DÉBITO) | S25: NFE VINCULADA | T25: I | U25: 2026-08-10 21:00:00.000 -0300 | V25: 139.90 | W25: 5.1260823e+43 | X25: 1. Com nota fiscal recolhida | Y25: 2026-08-15 00:00:00.000 -0300 | Z25: 2026-08-26 00:00:00.000 -0300 | AA25: 443177.07 | AD25: false | AE25: '51260822611652000103550010001719811020410220
A26: 90739624000118 | B26: GRITSCH - SNO | D26: SFD5C40 | E26: COMBUSTÍVEL | F26: 269308 | G26: 2026-08-11 16:39:34.000 -0300 | H26: 25054973 | I26: 342733 | J26: POSTO TREVAO GUARANTA | K26: 17084739000121 | L26: 90739624001866 | M26: 162.36 | N26: ABASTECIMENTO (DÉBITO) | S26: NFE VINCULADA | T26: I | U26: 2026-08-10 21:00:00.000 -0300 | V26: 162.36 | W26: 5.1260817e+43 | X26: 1. Com nota fiscal recolhida | Y26: 2026-08-15 00:00:00.000 -0300 | Z26: 2026-08-26 00:00:00.000 -0300 | AA26: 443177.07 | AD26: false | AE26: '51260817084739000121550010003427331007357872
A27: 90739624000118 | B27: GRITSCH - BLN | D27: RHL3E04 | E27: COMBUSTÍVEL | F27: 269308 | G27: 2026-08-11 16:36:05.000 -0300 | H27: 25054931 | I27: 130148 | J27: POSTO ZANDONA 12 | K27: 83392050000199 | L27: 90739624001432 | M27: 2457.91 | N27: ABASTECIMENTO (DÉBITO) | S27: NFE VINCULADA | T27: I | U27: 2026-08-10 21:00:00.000 -0300 | V27: 2457.91 | W27: 4.2260883e+43 | X27: 1. Com nota fiscal recolhida | Y27: 2026-08-15 00:00:00.000 -0300 | Z27: 2026-08-26 00:00:00.000 -0300 | AA27: 443177.07 | AD27: false | AE27: '42260883392050000199550020001301481111936167
A28: 90739624000118 | B28: GRITSCH - LDB | C28: 24754 | D28: SFI6J89 | E28: COMBUSTÍVEL | F28: 269308 | G28: 2026-08-11 16:34:42.000 -0300 | H28: 25054905 | I28: 10524 | J28: AUTO POSTO BARUK | K28: 33286065000102 | L28: 9576274000106 | M28: 350.27 | N28: ABASTECIMENTO (DÉBITO) | S28: NFE VINCULADA | T28: I | U28: 2026-08-10 21:00:00.000 -0300 | V28: 350.27 | W28: 4.1260833e+43 | X28: 1. Com nota fiscal recolhida | Y28: 2026-08-15 00:00:00.000 -0300 | Z28: 2026-08-26 00:00:00.000 -0300 | AA28: 443177.07 | AD28: false | AE28: '41260833286065000102550040000105241014217700
A29: 90739624000118 | B29: GRITSCH - CSC | C29: 23846 | D29: SEP6E33 | E29: COMBUSTÍVEL | F29: 269308 | G29: 2026-08-11 16:31:43.000 -0300 | H29: 25054777 | I29: 163223 | J29: POSTO NOVO FOXX - REDE ESTRADA | K29: 2763612000161 | L29: 90739624003133 | M29: 219.52 | N29: ABASTECIMENTO (DÉBITO) | S29: NFE VINCULADA | T29: I | U29: 2026-08-10 21:00:00.000 -0300 | V29: 219.52 | W29: 4.1260803e+43 | X29: 1. Com nota fiscal recolhida | Y29: 2026-08-15 00:00:00.000 -0300 | Z29: 2026-08-26 00:00:00.000 -0300 | AA29: 443177.07 | AD29: false | AE29: '41260802763612000161550020001632231469305060
A30: 90739624000118 | B30: GRITSCH - RVD | D30: SFI4A20 | E30: COMBUSTÍVEL | F30: 269308 | G30: 2026-08-11 16:31:41.000 -0300 | H30: 25054776 | I30: 6749 | J30: POSTO CPN - BR | K30: 23891404000118 | L30: 90739624001866 | M30: 230.47 | N30: ABASTECIMENTO (DÉBITO) | S30: NFE VINCULADA | T30: I | U30: 2026-08-13 21:00:00.000 -0300 | V30: 230.47 | W30: 5.1260824e+43 | X30: 1. Com nota fiscal recolhida | Y30: 2026-08-15 00:00:00.000 -0300 | Z30: 2026-08-26 00:00:00.000 -0300 | AA30: 443177.07 | AD30: false | AE30: '51260823891404000118551010000067491089991170
A31: 90739624000118 | B31: GRITSCH - CGR | C31: 26010 | D31: TAP3G60 | E31: COMBUSTÍVEL | F31: 269308 | G31: 2026-08-11 16:31:11.000 -0300 | H31: 25054770 | I31: 16711 | J31: POSTO SAN MARTIN | K31: 1550726000160 | L31: 90739624001190 | M31: 372.14 | N31: ABASTECIMENTO (DÉBITO) | S31: NFE VINCULADA | T31: I | U31: 2026-08-12 21:00:00.000 -0300 | V31: 372.14 | W31: 5.0260802e+43 | X31: 1. Com nota fiscal recolhida | Y31: 2026-08-15 00:00:00.000 -0300 | Z31: 2026-08-26 00:00:00.000 -0300 | AA31: 443177.07 | AD31: false | AE31: '50260801550726000160550030000167111130728365
A32: 90739624000118 | B32: GRITSCH - MGA | D32: SFD3E82 | E32: COMBUSTÍVEL | F32: 269308 | G32: 2026-08-11 16:22:55.000 -0300 | H32: 25054603 | I32: 41275 | J32: COCAMAR - MARINGA | REDE COCAMAR MARINGA - PR | K32: 30429333000282 | L32: 9576274000106 | M32: 168.71 | N32: ABASTECIMENTO (DÉBITO) | S32: NFE VINCULADA | T32: I | U32: 2026-08-10 21:00:00.000 -0300 | V32: 168.71 | W32: 4.126083e+43 | X32: 1. Com nota fiscal recolhida | Y32: 2026-08-15 00:00:00.000 -0300 | Z32: 2026-08-26 00:00:00.000 -0300 | AA32: 443177.07 | AD32: false | AE32: '41260830429333000282550110000412751005184719
A33: 90739624000118 | B33: GRITSCH - CTB | D33: TBQ1G07 | E33: ARLA | F33: 269308 | G33: 2026-08-11 16:06:38.000 -0300 | H33: 25054240 | I33: 168722 | J33: POSTO CAPITAL | K33: 82156977000248 | L33: 90739624001432 | M33: 26.32 | N33: ABASTECIMENTO (DÉBITO) | S33: NFE VINCULADA | T33: I | U33: 2026-08-10 21:00:00.000 -0300 | V33: 26.32 | W33: 4.2260882e+43 | X33: 1. Com nota fiscal recolhida | Y33: 2026-08-15 00:00:00.000 -0300 | Z33: 2026-08-26 00:00:00.000 -0300 | AA33: 443177.07 | AD33: false | AE33: '42260882156977000248550010001687221951919602
A34: 90739624000118 | B34: GRITSCH - CTB | D34: TBQ1G07 | E34: COMBUSTÍVEL | F34: 269308 | G34: 2026-08-11 16:05:33.000 -0300 | H34: 25054226 | I34: 168721 | J34: POSTO CAPITAL | K34: 82156977000248 | L34: 90739624001432 | M34: 221.6 | N34: ABASTECIMENTO (DÉBITO) | S34: NFE VINCULADA | T34: I | U34: 2026-08-10 21:00:00.000 -0300 | V34: 221.60 | W34: 4.2260882e+43 | X34: 1. Com nota fiscal recolhida | Y34: 2026-08-15 00:00:00.000 -0300 | Z34: 2026-08-26 00:00:00.000 -0300 | AA34: 443177.07 | AD34: false | AE34: '42260882156977000248550010001687211575440027
A35: 90739624000118 | B35: GRITSCH - CWB (BASE) | D35: SEL7G42 | E35: COMBUSTÍVEL | F35: 269308 | G35: 2026-08-11 16:04:53.000 -0300 | H35: 25054214 | I35: 389635 | J35: POSTO BARAO MATRIZ|| REDE BARAO | K35: 75176859000155 | L35: 9576274000106 | M35: 303.44 | N35: ABASTECIMENTO (DÉBITO) | S35: NFE VINCULADA | T35: I | U35: 2026-08-10 21:00:00.000 -0300 | V35: 303.44 | W35: 4.1260875e+43 | X35: 1. Com nota fiscal recolhida | Y35: 2026-08-15 00:00:00.000 -0300 | Z35: 2026-08-26 00:00:00.000 -0300 | AA35: 443177.07 | AD35: false | AE35: '41260875176859000155550020003896351760533255
A36: 90739624000118 | B36: GRITSCH - SNO | D36: SFN1H25 | E36: COMBUSTÍVEL | F36: 269308 | G36: 2026-08-11 16:02:33.000 -0300 | H36: 25054174 | I36: 74996 | J36: POSTO CASAGRANDA | K36: 1594553000182 | L36: 90739624001866 | M36: 61.05 | N36: ABASTECIMENTO (DÉBITO) | S36: NFE VINCULADA | T36: I | U36: 2026-08-10 21:00:00.000 -0300 | V36: 61.05 | W36: 5.1260802e+43 | X36: 1. Com nota fiscal recolhida | Y36: 2026-08-15 00:00:00.000 -0300 | Z36: 2026-08-26 00:00:00.000 -0300 | AA36: 443177.07 | AD36: false | AE36: '51260801594553000182550100000749961010486291
A37: 90739624000118 | B37: GRITSCH - CSC | D37: RHP7C51 | E37: COMBUSTÍVEL | F37: 269308 | G37: 2026-08-11 16:00:25.000 -0300 | H37: 25054149 | I37: 163217 | J37: POSTO NOVO FOXX - REDE ESTRADA | K37: 2763612000161 | L37: 90739624003133 | M37: 416.68 | N37: ABASTECIMENTO (DÉBITO) | S37: NFE VINCULADA | T37: I | U37: 2026-08-10 21:00:00.000 -0300 | V37: 416.68 | W37: 4.1260803e+43 | X37: 1. Com nota fiscal recolhida | Y37: 2026-08-15 00:00:00.000 -0300 | Z37: 2026-08-26 00:00:00.000 -0300 | AA37: 443177.07 | AD37: false | AE37: '41260802763612000161550020001632171858968259
A38: 90739624000118 | B38: GRITSCH - CTB | C38: 26121 | D38: TAS4H11 | E38: COMBUSTÍVEL | F38: 269308 | G38: 2026-08-11 15:57:50.000 -0300 | H38: 25054114 | I38: 168719 | J38: POSTO CAPITAL | K38: 82156977000248 | L38: 90739624001432 | M38: 232.82 | N38: ABASTECIMENTO (DÉBITO) | S38: NFE VINCULADA | T38: I | U38: 2026-08-10 21:00:00.000 -0300 | V38: 232.82 | W38: 4.2260882e+43 | X38: 1. Com nota fiscal recolhida | Y38: 2026-08-15 00:00:00.000 -0300 | Z38: 2026-08-26 00:00:00.000 -0300 | AA38: 443177.07 | AD38: false | AE38: '42260882156977000248550010001687191881791585
A39: 90739624000118 | B39: GRITSCH - CSC | C39: 25076 | D39: SFM3H46 | E39: COMBUSTÍVEL | F39: 269308 | G39: 2026-08-11 15:49:14.000 -0300 | H39: 25053900 | I39: 163214 | J39: POSTO NOVO FOXX - REDE ESTRADA | K39: 2763612000161 | L39: 90739624003133 | M39: 224.22 | N39: ABASTECIMENTO (DÉBITO) | S39: NFE VINCULADA | T39: I | U39: 2026-08-10 21:00:00.000 -0300 | V39: 224.22 | W39: 4.1260803e+43 | X39: 1. Com nota fiscal recolhida | Y39: 2026-08-15 00:00:00.000 -0300 | Z39: 2026-08-26 00:00:00.000 -0300 | AA39: 443177.07 | AD39: false | AE39: '41260802763612000161550020001632141373894715
A40: 90739624000118 | B40: GRITSCH - GOI | D40: SFD5C36 | E40: COMBUSTÍVEL | F40: 269308 | G40: 2026-08-11 15:48:24.000 -0300 | H40: 25053865 | I40: 81438 | J40: POSTO 10 GOIANIA | REDE CARRETEIRO | K40: 1272434001002 | L40: 90739624001947 | M40: 341.1 | N40: ABASTECIMENTO (DÉBITO) | S40: NFE VINCULADA | T40: I | U40: 2026-08-10 21:00:00.000 -0300 | V40: 341.10 | W40: 5.2260801e+43 | X40: 1. Com nota fiscal recolhida | Y40: 2026-08-15 00:00:00.000 -0300 | Z40: 2026-08-26 00:00:00.000 -0300 | AA40: 443177.07 | AD40: false | AE40: '52260801272434001002550020000814381308342643
...

Sheet Relatorio
A1: fatura | B1: categoria_relatorio | C1: placa | D1: garagem | E1: data_transacao | F1: id_transacao_atual | G1: nome_posto | H1: cnpj_posto | I1: cnpj_filial_nfe | J1: natureza_bluefllet | K1: valor_item_liquido | L1: status_fiscal | M1: numero_nota_fiscal | N1: nfe_data_emissao | O1: nfe_valor_nota | P1: chave_nfe | Q1: id_referencia_original | R1: fatura_origem_referencia | S1: fatura_credito_retorno | T1: data_credito_retorno | U1: titulo_data_vencimento
A2: 269308 | B2: 4. Crédito de estorno (desconto) | C2: SFL2F19 | D2: GRITSCH - CGB | E2: 2026-08-01 14:03:55.000 -0300 | F2: 25041264 | G2: POSTO SAO JOSE 1 | H2: 4903852000140 | J2: COMBUSTÍVEL | K2: -285.67 | L2: CRÉDITO / ESTORNO | Q2: 24567446 | R2: 267384 | U2: 2026-08-26 00:00:00.000 -0300
A3: 269308 | B3: 4. Crédito de estorno (desconto) | C3: UBR9A92 | D3: GRITSCH - POA | E3: 2026-07-28 18:26:06.000 -0300 | F3: 25041210 | G3: SIM REDE - ALEGRETE - 019877 - CENTRO RS | H3: 7473735019877 | J3: COMBUSTÍVEL | K3: -251.86 | L3: CRÉDITO / ESTORNO | Q3: 24375893 | R3: 267384 | U3: 2026-08-26 00:00:00.000 -0300
A4: 269308 | B4: 4. Crédito de estorno (desconto) | C4: UBN9E24 | D4: GRITSCH - PET | E4: 2026-07-31 08:16:17.000 -0300 | F4: 25030298 | G4: SIM REDE - PELOTAS FERNANDO OSORIO 0093-08 - CENTRO RS | H4: 7473735009308 | J4: COMBUSTÍVEL | K4: -141.68 | L4: CRÉDITO / ESTORNO | Q4: 24502758 | R4: 267384 | U4: 2026-08-26 00:00:00.000 -0300
A5: 269308 | B5: 4. Crédito de estorno (desconto) | C5: SDU9F98 | D5: GRITSCH - RVD | E5: 2026-08-07 10:14:51.000 -0300 | F5: 24861044 | G5: POSTO ALDO JATAI INDUSTRIAL - REDE ALDO | H5: 2651099000117 | J5: COMBUSTÍVEL | K5: -331.89 | L5: CRÉDITO / ESTORNO | Q5: 24860705 | R5: 269308 | U5: 2026-08-26 00:00:00.000 -0300
A6: 269308 | B6: 4. Crédito de estorno (desconto) | C6: TBE5I66 | D6: GRITSCH - GOI | E6: 2026-08-03 14:18:13.000 -0300 | F6: 25027473 | G6: POSTO SAO JUDAS TADEU - REDE Z+Z (RODOVIA) | H6: 13759928000104 | J6: COMBUSTÍVEL | K6: -231.70 | L6: CRÉDITO / ESTORNO | Q6: 24661956 | R6: 267384 | U6: 2026-08-26 00:00:00.000 -0300
A7: 269308 | B7: 4. Crédito de estorno (desconto) | C7: TBE5I66 | D7: GRITSCH - GOI | E7: 2026-07-30 15:13:04.000 -0300 | F7: 25029954 | G7: POSTO SAO JUDAS TADEU - REDE Z+Z (RODOVIA) | H7: 13759928000104 | J7: COMBUSTÍVEL | K7: -225.77 | L7: CRÉDITO / ESTORNO | Q7: 24469630 | R7: 267384 | U7: 2026-08-26 00:00:00.000 -0300
A8: 269308 | B8: 1. Com nota fiscal recolhida | C8: SFH7D75 | D8: GRITSCH - MATRIZ | E8: 2026-08-11 20:32:34.000 -0300 | F8: 25063040 | G8: POSTO 2 IRMAOS | H8: 76493295000147 | I8: 9576274000106 | J8: COMBUSTÍVEL | K8: 252.02 | L8: NFE VINCULADA | M8: 29106 | N8: 2026-08-10 21:00:00.000 -0300 | O8: 252.02 | P8: '41260876493295000147550020000291061002782187 | U8: 2026-08-26 00:00:00.000 -0300
A9: 269308 | B9: 1. Com nota fiscal recolhida | C9: TBK1J24 | D9: GRITSCH - RVD | E9: 2026-08-11 20:16:50.000 -0300 | F9: 25062781 | G9: REDE MONTE CARLO - POSTO SAO JOSE | H9: 42733072000198 | I9: 90739624000380 | J9: COMBUSTÍVEL | K9: 283.60 | L9: NFE VINCULADA | M9: 5325 | N9: 2026-08-11 21:00:00.000 -0300 | O9: 283.60 | P9: '35260842733072000198550080000053251524484620 | U9: 2026-08-26 00:00:00.000 -0300
A10: 269308 | B10: 1. Com nota fiscal recolhida | C10: UAV5J73 | D10: GRITSCH - GOI | E10: 2026-08-11 19:42:40.000 -0300 | F10: 25062357 | G10: AUTO POSTO CIDADE - PORANGATU | H10: 33360405000190 | I10: 90739624001947 | J10: COMBUSTÍVEL | K10: 220.77 | L10: NFE VINCULADA | M10: 38315 | N10: 2026-08-10 21:00:00.000 -0300 | O10: 220.77 | P10: '52260833360405000190550020000383151008888133 | U10: 2026-08-26 00:00:00.000 -0300
A11: 269308 | B11: 1. Com nota fiscal recolhida | C11: UCB6D90 | D11: GRITSCH - SAO (PERUS) | E11: 2026-08-11 19:17:08.000 -0300 | F11: 25061999 | G11: POSTO DO TREVO - REDE GRAAL | H11: 55973291000196 | I11: 90739624000380 | J11: COMBUSTÍVEL | K11: 336.50 | L11: NFE VINCULADA | M11: 1052949 | N11: 2026-08-10 21:00:00.000 -0300 | O11: 336.50 | P11: '35260855973291000196550030010529491018448930 | U11: 2026-08-26 00:00:00.000 -0300
A12: 269308 | B12: 1. Com nota fiscal recolhida | C12: UCC8A40 | D12: GRITSCH - CWB (BASE) | E12: 2026-08-11 19:14:36.000 -0300 | F12: 25061890 | G12: GP POSTOS - POSTO SAO JOSE | H12: 79964177000591 | I12: 9576274000106 | J12: COMBUSTÍVEL | K12: 698.82 | L12: NFE VINCULADA | M12: 820855 | N12: 2026-08-10 21:00:00.000 -0300 | O12: 698.82 | P12: '41260879964177000591550020008208551011758525 | U12: 2026-08-26 00:00:00.000 -0300
A13: 269308 | B13: 1. Com nota fiscal recolhida | C13: UAV5J75 | D13: GRITSCH - PMW | E13: 2026-08-11 19:09:13.000 -0300 | F13: 25061863 | G13: AUTO POSTO CIDADE - PORANGATU | H13: 33360405000190 | I13: 90739624001947 | J13: COMBUSTÍVEL | K13: 196.89 | L13: NFE VINCULADA | M13: 38314 | N13: 2026-08-10 21:00:00.000 -0300 | O13: 196.89 | P13: '52260833360405000190550020000383141008887997 | U13: 2026-08-26 00:00:00.000 -0300
A14: 269308 | B14: 1. Com nota fiscal recolhida | C14: BBW0C96 | D14: GRITSCH - CWB (BASE) | E14: 2026-08-11 18:36:53.000 -0300 | F14: 25061415 | G14: GP POSTOS - POSTO SAO JOSE | H14: 79964177000591 | I14: 9576274000106 | J14: COMBUSTÍVEL | K14: 1878.84 | L14: NFE VINCULADA | M14: 820852 | N14: 2026-08-10 21:00:00.000 -0300 | O14: 1878.84 | P14: '41260879964177000591550020008208521011758434 | U14: 2026-08-26 00:00:00.000 -0300
A15: 269308 | B15: 1. Com nota fiscal recolhida | C15: RHT0B69 | D15: GRITSCH - CHA | E15: 2026-08-11 18:33:59.000 -0300 | F15: 25061399 | G15: BUFFON 74 | H15: 93489243007471 | I15: 90739624002323 | J15: COMBUSTÍVEL | K15: 475.60 | L15: NFE VINCULADA | M15: 4439 | N15: 2026-08-10 21:00:00.000 -0300 | O15: 475.60 | P15: '43260893489243007471550080000044391522201280 | U15: 2026-08-26 00:00:00.000 -0300
A16: 269308 | B16: 1. Com nota fiscal recolhida | C16: TBE5I62 | D16: GRITSCH - GOI | E16: 2026-08-11 17:34:10.000 -0300 | F16: 25056047 | G16: POSTO 10 GOIANIA | REDE CARRETEIRO | H16: 1272434001002 | I16: 90739624001947 | J16: COMBUSTÍVEL | K16: 260.28 | L16: NFE VINCULADA | M16: 81440 | N16: 2026-08-10 21:00:00.000 -0300 | O16: 260.28 | P16: '52260801272434001002550020000814401274796734 | U16: 2026-08-26 00:00:00.000 -0300
A17: 269308 | B17: 1. Com nota fiscal recolhida | C17: TAS4H20 | D17: GRITSCH - SAO (PERUS) | E17: 2026-08-11 17:25:18.000 -0300 | F17: 25055879 | G17: AUTO POSTO LIMOEIRO - PALOMA - REDE GRAAL | H17: 5065447000162 | I17: 90739624000380 | J17: COMBUSTÍVEL | K17: 221.63 | L17: NFE VINCULADA | M17: 374251 | N17: 2026-08-10 21:00:00.000 -0300 | O17: 221.63 | P17: '35260805065447000162550060003742511006200254 | U17: 2026-08-26 00:00:00.000 -0300
A18: 269308 | B18: 1. Com nota fiscal recolhida | C18: SEI5B85 | D18: GRITSCH - RDN | E18: 2026-08-11 17:22:05.000 -0300 | F18: 25055759 | G18: REDE DINO - POSTO SERRA DAS ARARAS | H18: 50128357000551 | I18: 90739624001866 | J18: COMBUSTÍVEL | K18: 189.65 | L18: NFE VINCULADA | M18: 10286 | N18: 2026-08-10 21:00:00.000 -0300 | O18: 189.64 | P18: '51260850128357000551550050000102861001035117 | U18: 2026-08-26 00:00:00.000 -0300
A19: 269308 | B19: 1. Com nota fiscal recolhida | C19: TAI9A24 | D19: GRITSCH - POA | E19: 2026-08-11 17:17:58.000 -0300 | F19: 25055716 | G19: SIM REDE - ALEGRETE - 019877 - CENTRO RS | H19: 7473735019877 | I19: 90739624002323 | J19: COMBUSTÍVEL | K19: 255.16 | L19: NFE VINCULADA | M19: 58070 | N19: 2026-08-10 21:00:00.000 -0300 | O19: 255.16 | P19: '43260807473735019877550080000580701009183062 | U19: 2026-08-26 00:00:00.000 -0300
... A45: 269308 | B45: 1. Com nota fiscal recolhida | C45: TAI9A19 | D45: GRITSCH - GOI | E45: 2026-08-11 15:34:32.000 -0300 | F45: 25053634 | G45: POSTO CALIFORNIA - PASADENA | H45: 47377960000139 | I45: 90739624001947 | J45: COMBUSTÍVEL | K45: 210.91 | L45: NFE VINCULADA | M45: 113417 | N45: 2026-08-10 21:00:00.000 -0300 | O45: 210.90 | P45: '52260847377960000139550010001134171584734398 | U45: 2026-08-26 00:00:00.000 -0300
A46: 269308 | B46: 3. Sem nota fiscal | C46: UBR9A97 | D46: GRITSCH - POA | E46: 2026-08-11 15:33:34.000 -0300 | F46: 25053621 | G46: SIM REDE - URUGUAIANA BR 290 0152-94 - CENTRO RS | H46: 7473735015294 | J46: COMBUSTÍVEL | K46: 268.65 | L46: PENDENTE DE NOTA | U46: 2026-08-26 00:00:00.000 -0300
A47: 269308 | B47: 1. Com nota fiscal recolhida | C47: RHS8D41 | D47: GRITSCH - CWB (BASE) | E47: 2026-08-11 15:25:17.000 -0300 | F47: 25053293 | G47: POSTO JOINVILLE - GRUPO GISA | H47: 1975878000105 | I47: 9576274000106 | J47: COMBUSTÍVEL | K47: 250.31 | L47: NFE VINCULADA | M47: 2544 | N47: 2026-08-10 21:00:00.000 -0300 | O47: 250.31 | P47: '41260801975878000105550100000025441785364390 | U47: 2026-08-26 00:00:00.000 -0300
A48: 269308 | B48: 1. Com nota fiscal recolhida | C48: SFL1E46 | D48: GRITSCH - PMW | E48: 2026-08-11 15:23:18.000 -0300 | F48: 25053265 | G48: RODOPOSTO | H48: 4219621000111 | I48: 90739624000118 | J48: COMBUSTÍVEL | K48: 298.18 | L48: NFE VINCULADA | M48: 99279 | N48: 2026-08-11 21:00:00.000 -0300 | O48: 298.18 | P48: '17260804219621000111550010000992791349733063 | U48: 2026-08-26 00:00:00.000 -0300
A49: 269308 | B49: 3. Sem nota fiscal | C49: TAV9E95 | D49: GRITSCH - PET | E49: 2026-08-11 15:21:18.000 -0300 | F49: 25053242 | G49: SIM REDE - PELOTAS CAVADA 0060-31 - CENTRO RS | H49: 7473735006031 | J49: ARLA | K49: 42.42 | L49: PENDENTE DE NOTA | U49: 2026-08-26 00:00:00.000 -0300
A50: 269308 | B50: 1. Com nota fiscal recolhida | C50: UBA9H34 | D50: GRITSCH - RDN | E50: 2026-08-11 15:19:57.000 -0300 | F50: 25053230 | G50: REDE MARAJO BOM JARDIM DE GOIAS | H50: 58446194000133 | I50: 90739624001947 | J50: COMBUSTÍVEL | K50: 501.43 | L50: NFE VINCULADA | M50: 53347 | N50: 2026-08-10 21:00:00.000 -0300 | O50: 501.43 | P50: '52260858446194000133550540000533471818139992 | U50: 2026-08-26 00:00:00.000 -0300
A51: 269308 | B51: 3. Sem nota fiscal | C51: TAV9E95 | D51: GRITSCH - PET | E51: 2026-08-11 15:19:12.000 -0300 | F51: 25053221 | G51: SIM REDE - PELOTAS CAVADA 0060-31 - CENTRO RS | H51: 7473735006031 | J51: COMBUSTÍVEL | K51: 610.96 | L51: PENDENTE DE NOTA | U51: 2026-08-26 00:00:00.000 -0300
A52: 269308 | B52: 1. Com nota fiscal recolhida | C52: SEL0E76 | D52: GRITSCH - RDN | E52: 2026-08-11 15:19:08.000 -0300 | F52: 25053220 | G52: POSTO CPN - BR | H52: 23891404000118 | I52: 90739624001866 | J52: ARLA | K52: 48.25 | L52: NFE VINCULADA | M52: 131912 | N52: 2026-08-10 21:00:00.000 -0300 | O52: 48.25 | P52: '51260823891404000118550110001319121621930536 | U52: 2026-08-26 00:00:00.000 -0300
A53: 269308 | B53: 1. Com nota fiscal recolhida | C53: SEL0E76 | D53: GRITSCH - RDN | E53: 2026-08-11 15:17:45.000 -0300 | F53: 25053155 | G53: POSTO CPN - BR | H53: 23891404000118 | I53: 90739624001866 | J53: COMBUSTÍVEL | K53: 403.27 | L53: NFE VINCULADA | M53: 131911 | N53: 2026-08-10 21:00:00.000 -0300 | O53: 403.27 | P53: '51260823891404000118550110001319111895139898 | U53: 2026-08-26 00:00:00.000 -0300
A54: 269308 | B54: 1. Com nota fiscal recolhida | C54: TAZ4A48 | D54: GRITSCH - CSC | E54: 2026-08-11 15:16:55.000 -0300 | F54: 25053095 | G54: POSTO NOVO FOXX - REDE ESTRADA | H54: 2763612000161 | I54: 90739624003133 | J54: COMBUSTÍVEL | K54: 233.90 | L54: NFE VINCULADA | M54: 163210 | N54: 2026-08-10 21:00:00.000 -0300 | O54: 233.90 | P54: '41260802763612000161550020001632101317347268 | U54: 2026-08-26 00:00:00.000 -0300
A55: 269308 | B55: 1. Com nota fiscal recolhida | C55: SFM3H40 | D55: GRITSCH - CWB (BASE) | E55: 2026-08-11 15:06:58.000 -0300 | F55: 25052856 | G55: POSTO BARAO MATRIZ|| REDE BARAO | H55: 75176859000155 | I55: 9576274000106 | J55: COMBUSTÍVEL | K55: 244.80 | L55: NFE VINCULADA | M55: 389606 | N55: 2026-08-10 21:00:00.000 -0300 | O55: 244.80 | P55: '41260875176859000155550020003896061768635314 | U55: 2026-08-26 00:00:00.000 -0300
A56: 269308 | B56: 1. Com nota fiscal recolhida | C56: TAI4J01 | D56: GRITSCH - JOI | E56: 2026-08-11 14:44:25.000 -0300 | F56: 25051437 | G56: POSTO ZANDONA 7 | H56: 84711084000161 | I56: 90739624001432 | J56: COMBUSTÍVEL | K56: 273.03 | L56: NFE VINCULADA | M56: 119563 | N56: 2026-08-10 21:00:00.000 -0300 | O56: 273.03 | P56: '42260884711084000161550030001195631111744337 | U56: 2026-08-26 00:00:00.000 -0300
A57: 269308 | B57: 3. Sem nota fiscal | C57: RHS8D32 | D57: GRITSCH - CGB | E57: 2026-08-11 14:40:28.000 -0300 | F57: 25051004 | G57: AMAZONIA - 24 | H57: 9001879002619 | J57: COMBUSTÍVEL | K57: 95.08 | L57: PENDENTE DE NOTA | U57: 2026-08-26 00:00:00.000 -0300
A58: 269308 | B58: 1. Com nota fiscal recolhida | C58: TAW7H31 | D58: GRITSCH - LDB | E58: 2026-08-11 14:29:03.000 -0300 | F58: 25050039 | G58: AUTO POSTO BARUK | H58: 33286065000102 | I58: 9576274000106 | J58: ARLA | K58: 36.84 | L58: NFE VINCULADA | M58: 4450 | N58: 2026-08-10 21:00:00.000 -0300 | O58: 36.84 | P58: '41260833286065000102550100000044501014216827 | U58: 2026-08-26 00:00:00.000 -0300
A59: 269308 | B59: 1. Com nota fiscal recolhida | C59: SEL2B40 | D59: GRITSCH - PGR | E59: 2026-08-11 14:28:45.000 -0300 | F59: 25050026 | G59: POSTO ZAPA MARIUCA | REDE PRIMOS | H59: 27933025000102 | I59: 9576274000106 | J59: COMBUSTÍVEL | K59: 458.95 | L59: NFE VINCULADA | M59: 1150 | N59: 2026-08-13 21:00:00.000 -0300 | O59: 458.95 | P59: '41260827933025000102550090000011501000267280 | U59: 2026-08-26 00:00:00.000 -0300
A60: 269308 | B60: 1. Com nota fiscal recolhida | C60: TAW7H31 | D60: GRITSCH - LDB | E60: 2026-08-11 14:28:03.000 -0300 | F60: 25049964 | G60: AUTO POSTO BARUK | H60: 33286065000102 | I60: 9576274000106 | J60: COMBUSTÍVEL | K60: 758.53 | L60: NFE VINCULADA | M60: 4449 | N60: 2026-08-10 21:00:00.000 -0300 | O60: 758.53 | P60: '41260833286065000102550100000044491014216800 | U60: 2026-08-26 00:00:00.000 -0300
A61: 269308 | B61: 1. Com nota fiscal recolhida | C61: SFN1H25 | D61: GRITSCH - SNO | E61: 2026-08-11 14:27:09.000 -0300 | F61: 25049882 | G61: AUTO POSTO NOVO CEU | H61: 26602128000119 | I61: 90739624001866 | J61: COMBUSTÍVEL | K61: 142.63 | L61: NFE VINCULADA | M61: 136247 | N61: 2026-08-10 21:00:00.000 -0300 | O61: 142.63 | P61: '51260826602128000119550010001362471001773245 | U61: 2026-08-26 00:00:00.000 -0300
A62: 269308 | B62: 3. Sem nota fiscal | C62: UBD6I31 | D62: GRITSCH - CXJ | E62: 2026-08-11 14:26:45.000 -0300 | F62: 25049849 | G62: SIM REDE - CAXIAS DO SUL 0123-50 - METROPOLITANA / SERRA | H62: 7473735012350 | J62: COMBUSTÍVEL | K62: 377.78 | L62: PENDENTE DE NOTA | U62: 2026-08-26 00:00:00.000 -0300
A63: 269308 | B63: 1. Com nota fiscal recolhida | C63: SEZ3A79 | D63: GRITSCH - CTB | E63: 2026-08-11 14:22:55.000 -0300 | F63: 25049390 | G63: POSTO CAPITAL | H63: 82156977000248 | I63: 90739624001432 | J63: COMBUSTÍVEL | K63: 243.90 | L63: NFE VINCULADA | M63: 168705 | N63: 2026-08-10 21:00:00.000 -0300 | O63: 243.90 | P63: '42260882156977000248550010001687051986882038 | U63: 2026-08-26 00:00:00.000 -0300
A64: 269308 | B64: 1. Com nota fiscal recolhida | C64: RHQ6I66 | D64: GRITSCH - MGA | E64: 2026-08-11 14:22:01.000 -0300 | F64: 25049333 | G64: POSTO UNIDO | H64: 79130647000198 | I64: 9576274000106 | J64: COMBUSTÍVEL | K64: 383.75 | L64: NFE VINCULADA | M64: 16856 | N64: 2026-08-10 21:00:00.000 -0300 | O64: 383.75 | P64: '41260879130647000198550050000168561015904426 | U64: 2026-08-26 00:00:00.000 -0300
A65: 269308 | B65: 1. Com nota fiscal recolhida | C65: RHQ6I69 | D65: GRITSCH - MGA | E65: 2026-08-11 14:21:17.000 -0300 | F65: 25049271 | G65: POSTO UNIDO | H65: 79130647000198 | I65: 9576274000106 | J65: COMBUSTÍVEL | K65: 61.14 | L65: NFE VINCULADA | M65: 3023 | N65: 2026-08-10 21:00:00.000 -0300 | O65: 61.14 | P65: '41260879130647000198550070000030231015904419 | U65: 2026-08-26 00:00:00.000 -0300
...

Sheet Rateio por Garagem
A1: Garagem | B1: COLETADO | E1: NÃO COLETADO
B2: Coletado c/ NF | C2: Estornos (Crédito) | D2: Total Coletado Líquido | E2: Ab. Cancelado | F2: Sem NF | G2: Total Não Coletado | H2: Total Geral | I2: % do Total
A3: GRITSCH - BLN | B3: =SUMIFS(Contabilidade!$M:$M,Contabilidade!$B:$B,A3,Contabilidade!$X:$X,"1. Com nota fiscal recolhida") -> 18543.19 | C3: =SUMIFS(Contabilidade!$M:$M,Contabilidade!$B:$B,A3,Contabilidade!$X:$X,"4. Crédito de estorno (desconto)") -> 0 | D3: =B3+C3 -> 18543.19 | E3: =SUMIFS(Contabilidade!$M:$M,Contabilidade!$B:$B,A3,Contabilidade!$X:$X,"2. Abastecimento cancelado (sem nota)") -> 0 | F3: =SUMIFS(Contabilidade!$M:$M,Contabilidade!$B:$B,A3,Contabilidade!$X:$X,"3. Sem nota fiscal") -> 185.25 | G3: =E3+F3 -> 185.25 | H3: =D3+G3 -> 18728.44 | I3: =IF(H$32<>0,H3/H$32,0) -> 0.042259497
A4: GRITSCH - BSB | B4: =SUMIFS(Contabilidade!$M:$M,Contabilidade!$B:$B,A4,Contabilidade!$X:$X,"1. Com nota fiscal recolhida") -> 6122.22 | C4: =SUMIFS(Contabilidade!$M:$M,Contabilidade!$B:$B,A4,Contabilidade!$X:$X,"4. Crédito de estorno (desconto)") -> 0 | D4: =B4+C4 -> 6122.22 | E4: =SUMIFS(Contabilidade!$M:$M,Contabilidade!$B:$B,A4,Contabilidade!$X:$X,"2. Abastecimento cancelado (sem nota)") -> 0 | F4: =SUMIFS(Contabilidade!$M:$M,Contabilidade!$B:$B,A4,Contabilidade!$X:$X,"3. Sem nota fiscal") -> 268.52 | G4: =E4+F4 -> 268.52 | H4: =D4+G4 -> 6390.74 | I4: =IF(H$32<>0,H4/H$32,0) -> 0.014420286
A5: GRITSCH - CGB | B5: =SUMIFS(Contabilidade!$M:$M,Contabilidade!$B:$B,A5,Contabilidade!$X:$X,"1. Com nota fiscal recolhida") -> 9370.68 | C5: =SUMIFS(Contabilidade!$M:$M,Contabilidade!$B:$B,A5,Contabilidade!$X:$X,"4. Crédito de estorno (desconto)") -> -285.67 | D5: =B5+C5 -> 9085.01 | E5: =SUMIFS(Contabilidade!$M:$M,Contabilidade!$B:$B,A5,Contabilidade!$X:$X,"2. Abastecimento cancelado (sem nota)") -> 0 | F5: =SUMIFS(Contabilidade!$M:$M,Contabilidade!$B:$B,A5,Contabilidade!$X:$X,"3. Sem nota fiscal") -> 766.29 | G5: =E5+F5 -> 766.29 | H5: =D5+G5 -> 9851.3 | I5: =IF(H$32<>0,H5/H$32,0) -> 0.022228813
A6: GRITSCH - CGR | B6: =SUMIFS(Contabilidade!$M:$M,Contabilidade!$B:$B,A6,Contabilidade!$X:$X,"1. Com nota fiscal recolhida") -> 11931.65 | C6: =SUMIFS(Contabilidade!$M:$M,Contabilidade!$B:$B,A6,Contabilidade!$X:$X,"4. Crédito de estorno (desconto)") -> 0 | D6: =B6+C6 -> 11931.65 | E6: =SUMIFS(Contabilidade!$M:$M,Contabilidade!$B:$B,A6,Contabilidade!$X:$X,"2. Abastecimento cancelado (sem nota)") -> 0 | F6: =SUMIFS(Contabilidade!$M:$M,Contabilidade!$B:$B,A6,Contabilidade!$X:$X,"3. Sem nota fiscal") -> 2027 | G6: =E6+F6 -> 2027 | H6: =D6+G6 -> 13958.65 | I6: =IF(H$32<>0,H6/H$32,0) -> 0.031496778
A7: GRITSCH - CHA | B7: =SUMIFS(Contabilidade!$M:$M,Contabilidade!$B:$B,A7,Contabilidade!$X:$X,"1. Com nota fiscal recolhida") -> 16597.92 | C7: =SUMIFS(Contabilidade!$M:$M,Contabilidade!$B:$B,A7,Contabilidade!$X:$X,"4. Crédito de estorno (desconto)") -> 0 | D7: =B7+C7 -> 16597.92 | E7: =SUMIFS(Contabilidade!$M:$M,Contabilidade!$B:$B,A7,Contabilidade!$X:$X,"2. Abastecimento cancelado (sem nota)") -> 0 | F7: =SUMIFS(Contabilidade!$M:$M,Contabilidade!$B:$B,A7,Contabilidade!$X:$X,"3. Sem nota fiscal") -> 0 | G7: =E7+F7 -> 0 | H7: =D7+G7 -> 16597.92 | I7: =IF(H$32<>0,H7/H$32,0) -> 0.037452118
A8: GRITSCH - CRI | B8: =SUMIFS(Contabilidade!$M:$M,Contabilidade!$B:$B,A8,Contabilidade!$X:$X,"1. Com nota fiscal recolhida") -> 6880.57 | C8: =SUMIFS(Contabilidade!$M:$M,Contabilidade!$B:$B,A8,Contabilidade!$X:$X,"4. Crédito de estorno (desconto)") -> 0 | D8: =B8+C8 -> 6880.57 | E8: =SUMIFS(Contabilidade!$M:$M,Contabilidade!$B:$B,A8,Contabilidade!$X:$X,"2. Abastecimento cancelado (sem nota)") -> 0 | F8: =SUMIFS(Contabilidade!$M:$M,Contabilidade!$B:$B,A8,Contabilidade!$X:$X,"3. Sem nota fiscal") -> 221.24 | G8: =E8+F8 -> 221.24 | H8: =D8+G8 -> 7101.81 | I8: =IF(H$32<>0,H8/H$32,0) -> 0.016024769
A9: GRITSCH - CSC | B9: =SUMIFS(Contabilidade!$M:$M,Contabilidade!$B:$B,A9,Contabilidade!$X:$X,"1. Com nota fiscal recolhida") -> 13041.49 | C9: =SUMIFS(Contabilidade!$M:$M,Contabilidade!$B:$B,A9,Contabilidade!$X:$X,"4. Crédito de estorno (desconto)") -> 0 | D9: =B9+C9 -> 13041.49 | E9: =SUMIFS(Contabilidade!$M:$M,Contabilidade!$B:$B,A9,Contabilidade!$X:$X,"2. Abastecimento cancelado (sem nota)") -> 0 | F9: =SUMIFS(Contabilidade!$M:$M,Contabilidade!$B:$B,A9,Contabilidade!$X:$X,"3. Sem nota fiscal") -> 0 | G9: =E9+F9 -> 0 | H9: =D9+G9 -> 13041.49 | I9: =IF(H$32<>0,H9/H$32,0) -> 0.029427267
A10: GRITSCH - CTB | B10: =SUMIFS(Contabilidade!$M:$M,Contabilidade!$B:$B,A10,Contabilidade!$X:$X,"1. Com nota fiscal recolhida") -> 14854.96 | C10: =SUMIFS(Contabilidade!$M:$M,Contabilidade!$B:$B,A10,Contabilidade!$X:$X,"4. Crédito de estorno (desconto)") -> 0 | D10: =B10+C10 -> 14854.96 | E10: =SUMIFS(Contabilidade!$M:$M,Contabilidade!$B:$B,A10,Contabilidade!$X:$X,"2. Abastecimento cancelado (sem nota)") -> 0 | F10: =SUMIFS(Contabilidade!$M:$M,Contabilidade!$B:$B,A10,Contabilidade!$X:$X,"3. Sem nota fiscal") -> 0 | G10: =E10+F10 -> 0 | H10: =D10+G10 -> 14854.96 | I10: =IF(H$32<>0,H10/H$32,0) -> 0.033519243
A11: GRITSCH - CWB (BASE) | B11: =SUMIFS(Contabilidade!$M:$M,Contabilidade!$B:$B,A11,Contabilidade!$X:$X,"1. Com nota fiscal recolhida") -> 105145.34 | C11: =SUMIFS(Contabilidade!$M:$M,Contabilidade!$B:$B,A11,Contabilidade!$X:$X,"4. Crédito de estorno (desconto)") -> 0 | D11: =B11+C11 -> 105145.34 | E11: =SUMIFS(Contabilidade!$M:$M,Contabilidade!$B:$B,A11,Contabilidade!$X:$X,"2. Abastecimento cancelado (sem nota)") -> 0 | F11: =SUMIFS(Contabilidade!$M:$M,Contabilidade!$B:$B,A11,Contabilidade!$X:$X,"3. Sem nota fiscal") -> 1349.28 | G11: =E11+F11 -> 1349.28 | H11: =D11+G11 -> 106494.62 | I11: =IF(H$32<>0,H11/H$32,0) -> 0.24029813
A12: GRITSCH - CWB (DIR) | B12: =SUMIFS(Contabilidade!$M:$M,Contabilidade!$B:$B,A12,Contabilidade!$X:$X,"1. Com nota fiscal recolhida") -> 663.33 | C12: =SUMIFS(Contabilidade!$M:$M,Contabilidade!$B:$B,A12,Contabilidade!$X:$X,"4. Crédito de estorno (desconto)") -> 0 | D12: =B12+C12 -> 663.33 | E12: =SUMIFS(Contabilidade!$M:$M,Contabilidade!$B:$B,A12,Contabilidade!$X:$X,"2. Abastecimento cancelado (sem nota)") -> 0 | F12: =SUMIFS(Contabilidade!$M:$M,Contabilidade!$B:$B,A12,Contabilidade!$X:$X,"3. Sem nota fiscal") -> 0 | G12: =E12+F12 -> 0 | H12: =D12+G12 -> 663.33 | I12: =IF(H$32<>0,H12/H$32,0) -> 0.0014967607
A13: GRITSCH - CXJ | B13: =SUMIFS(Contabilidade!$M:$M,Contabilidade!$B:$B,A13,Contabilidade!$X:$X,"1. Com nota fiscal recolhida") -> 3069.99 | C13: =SUMIFS(Contabilidade!$M:$M,Contabilidade!$B:$B,A13,Contabilidade!$X:$X,"4. Crédito de estorno (desconto)") -> 0 | D13: =B13+C13 -> 3069.99 | E13: =SUMIFS(Contabilidade!$M:$M,Contabilidade!$B:$B,A13,Contabilidade!$X:$X,"2. Abastecimento cancelado (sem nota)") -> 0 | F13: =SUMIFS(Contabilidade!$M:$M,Contabilidade!$B:$B,A13,Contabilidade!$X:$X,"3. Sem nota fiscal") -> 3868.99 | G13: =E13+F13 -> 3868.99 | H13: =D13+G13 -> 6938.98 | I13: =IF(H$32<>0,H13/H$32,0) -> 0.015657353
A14: GRITSCH - FLN | B14: =SUMIFS(Contabilidade!$M:$M,Contabilidade!$B:$B,A14,Contabilidade!$X:$X,"1. Com nota fiscal recolhida") -> 25659.95 | C14: =SUMIFS(Contabilidade!$M:$M,Contabilidade!$B:$B,A14,Contabilidade!$X:$X,"4. Crédito de estorno (desconto)") -> 0 | D14: =B14+C14 -> 25659.95 | E14: =SUMIFS(Contabilidade!$M:$M,Contabilidade!$B:$B,A14,Contabilidade!$X:$X,"2. Abastecimento cancelado (sem nota)") -> 0 | F14: =SUMIFS(Contabilidade!$M:$M,Contabilidade!$B:$B,A14,Contabilidade!$X:$X,"3. Sem nota fiscal") -> 0 | G14: =E14+F14 -> 0 | H14: =D14+G14 -> 25659.95 | I14: =IF(H$32<>0,H14/H$32,0) -> 0.057899995
... A31: REFERENCIA CURITIBA | B31: =SUMIFS(Contabilidade!$M:$M,Contabilidade!$B:$B,A31,Contabilidade!$X:$X,"1. Com nota fiscal recolhida") -> 3986.55 | C31: =SUMIFS(Contabilidade!$M:$M,Contabilidade!$B:$B,A31,Contabilidade!$X:$X,"4. Crédito de estorno (desconto)") -> 0 | D31: =B31+C31 -> 3986.55 | E31: =SUMIFS(Contabilidade!$M:$M,Contabilidade!$B:$B,A31,Contabilidade!$X:$X,"2. Abastecimento cancelado (sem nota)") -> 0 | F31: =SUMIFS(Contabilidade!$M:$M,Contabilidade!$B:$B,A31,Contabilidade!$X:$X,"3. Sem nota fiscal") -> 0 | G31: =E31+F31 -> 0 | H31: =D31+G31 -> 3986.55 | I31: =IF(H$32<>0,H31/H$32,0) -> 0.0089953887
A32: TOTAL | B32: =SUM(B3:B31) -> 414653.7 | C32: =SUM(C3:C31) -> -1468.57 | D32: =SUM(D3:D31) -> 413185.13 | E32: =SUM(E3:E31) -> 331.89 | F32: =SUM(F3:F31) -> 29660.05 | G32: =SUM(G3:G31) -> 29991.94 | H32: =SUM(H3:H31) -> 443177.07 | I32: =SUM(I3:I31) -> 1

Sheet Rateio por Posto
A1: Nome do Posto | B1: CNPJ do Posto | C1: COLETADO | F1: NÃO COLETADO
C2: Coletado c/ NF | D2: Estornos (Crédito) | E2: Total Coletado Líquido | F2: Ab. Cancelado | G2: Sem NF | H2: Total Não Coletado | I2: Total Geral | J2: % do Total
A3: AMAZONIA - 24 | B3: =IFERROR(INDEX(Contabilidade!$K:$K,MATCH($A3,Contabilidade!$J:$J,0)),"") -> 9001879002619 | C3: =SUMIFS(Contabilidade!$M:$M,Contabilidade!$J:$J,$A3,Contabilidade!$X:$X,"1. Com nota fiscal recolhida") -> 0 | D3: =SUMIFS(Contabilidade!$M:$M,Contabilidade!$J:$J,$A3,Contabilidade!$X:$X,"4. Crédito de estorno (desconto)") -> 0 | E3: =C3+D3 -> 0 | F3: =SUMIFS(Contabilidade!$M:$M,Contabilidade!$J:$J,$A3,Contabilidade!$X:$X,"2. Abastecimento cancelado (sem nota)") -> 0 | G3: =SUMIFS(Contabilidade!$M:$M,Contabilidade!$J:$J,$A3,Contabilidade!$X:$X,"3. Sem nota fiscal") -> 1936.51 | H3: =F3+G3 -> 1936.51 | I3: =E3+H3 -> 1936.51 | J3: =IF(I$208,I3/I$208,0) -> 0.0043696078
A4: AUTO POSTO AMARANTE | B4: =IFERROR(INDEX(Contabilidade!$K:$K,MATCH($A4,Contabilidade!$J:$J,0)),"") -> 5291412000141 | C4: =SUMIFS(Contabilidade!$M:$M,Contabilidade!$J:$J,$A4,Contabilidade!$X:$X,"1. Com nota fiscal recolhida") -> 718.7 | D4: =SUMIFS(Contabilidade!$M:$M,Contabilidade!$J:$J,$A4,Contabilidade!$X:$X,"4. Crédito de estorno (desconto)") -> 0 | E4: =C4+D4 -> 718.7 | F4: =SUMIFS(Contabilidade!$M:$M,Contabilidade!$J:$J,$A4,Contabilidade!$X:$X,"2. Abastecimento cancelado (sem nota)") -> 0 | G4: =SUMIFS(Contabilidade!$M:$M,Contabilidade!$J:$J,$A4,Contabilidade!$X:$X,"3. Sem nota fiscal") -> 0 | H4: =F4+G4 -> 0 | I4: =E4+H4 -> 718.7 | J4: =IF(I$208,I4/I$208,0) -> 0.0016216994
A5: AUTO POSTO BANDEIRANTES - JUARA | B5: =IFERROR(INDEX(Contabilidade!$K:$K,MATCH($A5,Contabilidade!$J:$J,0)),"") -> 22620102000142 | C5: =SUMIFS(Contabilidade!$M:$M,Contabilidade!$J:$J,$A5,Contabilidade!$X:$X,"1. Com nota fiscal recolhida") -> 103.6 | D5: =SUMIFS(Contabilidade!$M:$M,Contabilidade!$J:$J,$A5,Contabilidade!$X:$X,"4. Crédito de estorno (desconto)") -> 0 | E5: =C5+D5 -> 103.6 | F5: =SUMIFS(Contabilidade!$M:$M,Contabilidade!$J:$J,$A5,Contabilidade!$X:$X,"2. Abastecimento cancelado (sem nota)") -> 0 | G5: =SUMIFS(Contabilidade!$M:$M,Contabilidade!$J:$J,$A5,Contabilidade!$X:$X,"3. Sem nota fiscal") -> 0 | H5: =F5+G5 -> 0 | I5: =E5+H5 -> 103.6 | J5: =IF(I$208,I5/I$208,0) -> 0.00023376661
A6: AUTO POSTO BARUK | B6: =IFERROR(INDEX(Contabilidade!$K:$K,MATCH($A6,Contabilidade!$J:$J,0)),"") -> 33286065000102 | C6: =SUMIFS(Contabilidade!$M:$M,Contabilidade!$J:$J,$A6,Contabilidade!$X:$X,"1. Com nota fiscal recolhida") -> 15588.05 | D6: =SUMIFS(Contabilidade!$M:$M,Contabilidade!$J:$J,$A6,Contabilidade!$X:$X,"4. Crédito de estorno (desconto)") -> 0 | E6: =C6+D6 -> 15588.05 | F6: =SUMIFS(Contabilidade!$M:$M,Contabilidade!$J:$J,$A6,Contabilidade!$X:$X,"2. Abastecimento cancelado (sem nota)") -> 0 | G6: =SUMIFS(Contabilidade!$M:$M,Contabilidade!$J:$J,$A6,Contabilidade!$X:$X,"3. Sem nota fiscal") -> 0 | H6: =F6+G6 -> 0 | I6: =E6+H6 -> 15588.05 | J6: =IF(I$208,I6/I$208,0) -> 0.035173413
A7: AUTO POSTO BATISTELLA | B7: =IFERROR(INDEX(Contabilidade!$K:$K,MATCH($A7,Contabilidade!$J:$J,0)),"") -> 44746308000156 | C7: =SUMIFS(Contabilidade!$M:$M,Contabilidade!$J:$J,$A7,Contabilidade!$X:$X,"1. Com nota fiscal recolhida") -> 668.2 | D7: =SUMIFS(Contabilidade!$M:$M,Contabilidade!$J:$J,$A7,Contabilidade!$X:$X,"4. Crédito de estorno (desconto)") -> 0 | E7: =C7+D7 -> 668.2 | F7: =SUMIFS(Contabilidade!$M:$M,Contabilidade!$J:$J,$A7,Contabilidade!$X:$X,"2. Abastecimento cancelado (sem nota)") -> 0 | G7: =SUMIFS(Contabilidade!$M:$M,Contabilidade!$J:$J,$A7,Contabilidade!$X:$X,"3. Sem nota fiscal") -> 0 | H7: =F7+G7 -> 0 | I7: =E7+H7 -> 668.2 | J7: =IF(I$208,I7/I$208,0) -> 0.0015077495
A8: AUTO POSTO BRASILIA 2 | B8: =IFERROR(INDEX(Contabilidade!$K:$K,MATCH($A8,Contabilidade!$J:$J,0)),"") -> 2162964000161 | C8: =SUMIFS(Contabilidade!$M:$M,Contabilidade!$J:$J,$A8,Contabilidade!$X:$X,"1. Com nota fiscal recolhida") -> 662.78 | D8: =SUMIFS(Contabilidade!$M:$M,Contabilidade!$J:$J,$A8,Contabilidade!$X:$X,"4. Crédito de estorno (desconto)") -> 0 | E8: =C8+D8 -> 662.78 | F8: =SUMIFS(Contabilidade!$M:$M,Contabilidade!$J:$J,$A8,Contabilidade!$X:$X,"2. Abastecimento cancelado (sem nota)") -> 0 | G8: =SUMIFS(Contabilidade!$M:$M,Contabilidade!$J:$J,$A8,Contabilidade!$X:$X,"3. Sem nota fiscal") -> 0 | H8: =F8+G8 -> 0 | I8: =E8+H8 -> 662.78 | J8: =IF(I$208,I8/I$208,0) -> 0.0014955196
A9: AUTO POSTO CHEGADAO | B9: =IFERROR(INDEX(Contabilidade!$K:$K,MATCH($A9,Contabilidade!$J:$J,0)),"") -> 3680814000102 | C9: =SUMIFS(Contabilidade!$M:$M,Contabilidade!$J:$J,$A9,Contabilidade!$X:$X,"1. Com nota fiscal recolhida") -> 1040.22 | D9: =SUMIFS(Contabilidade!$M:$M,Contabilidade!$J:$J,$A9,Contabilidade!$X:$X,"4. Crédito de estorno (desconto)") -> 0 | E9: =C9+D9 -> 1040.22 | F9: =SUMIFS(Contabilidade!$M:$M,Contabilidade!$J:$J,$A9,Contabilidade!$X:$X,"2. Abastecimento cancelado (sem nota)") -> 0 | G9: =SUMIFS(Contabilidade!$M:$M,Contabilidade!$J:$J,$A9,Contabilidade!$X:$X,"3. Sem nota fiscal") -> 0 | H9: =F9+G9 -> 0 | I9: =E9+H9 -> 1040.22 | J9: =IF(I$208,I9/I$208,0) -> 0.0023471882
A10: AUTO POSTO CIDADE - PORANGATU | B10: =IFERROR(INDEX(Contabilidade!$K:$K,MATCH($A10,Contabilidade!$J:$J,0)),"") -> 33360405000190 | C10: =SUMIFS(Contabilidade!$M:$M,Contabilidade!$J:$J,$A10,Contabilidade!$X:$X,"1. Com nota fiscal recolhida") -> 4803.69 | D10: =SUMIFS(Contabilidade!$M:$M,Contabilidade!$J:$J,$A10,Contabilidade!$X:$X,"4. Crédito de estorno (desconto)") -> 0 | E10: =C10+D10 -> 4803.69 | F10: =SUMIFS(Contabilidade!$M:$M,Contabilidade!$J:$J,$A10,Contabilidade!$X:$X,"2. Abastecimento cancelado (sem nota)") -> 0 | G10: =SUMIFS(Contabilidade!$M:$M,Contabilidade!$J:$J,$A10,Contabilidade!$X:$X,"3. Sem nota fiscal") -> 0 | H10: =F10+G10 -> 0 | I10: =E10+H10 -> 4803.69 | J10: =IF(I$208,I10/I$208,0) -> 0.010839212
A11: AUTO POSTO CIMATEL | B11: =IFERROR(INDEX(Contabilidade!$K:$K,MATCH($A11,Contabilidade!$J:$J,0)),"") -> 656619000230 | C11: =SUMIFS(Contabilidade!$M:$M,Contabilidade!$J:$J,$A11,Contabilidade!$X:$X,"1. Com nota fiscal recolhida") -> 187.94 | D11: =SUMIFS(Contabilidade!$M:$M,Contabilidade!$J:$J,$A11,Contabilidade!$X:$X,"4. Crédito de estorno (desconto)") -> 0 | E11: =C11+D11 -> 187.94 | F11: =SUMIFS(Contabilidade!$M:$M,Contabilidade!$J:$J,$A11,Contabilidade!$X:$X,"2. Abastecimento cancelado (sem nota)") -> 0 | G11: =SUMIFS(Contabilidade!$M:$M,Contabilidade!$J:$J,$A11,Contabilidade!$X:$X,"3. Sem nota fiscal") -> 0 | H11: =F11+G11 -> 0 | I11: =E11+H11 -> 187.94 | J11: =IF(I$208,I11/I$208,0) -> 0.00042407429
A12: AUTO POSTO CONFIANCA | B12: =IFERROR(INDEX(Contabilidade!$K:$K,MATCH($A12,Contabilidade!$J:$J,0)),"") -> 8810726000100 | C12: =SUMIFS(Contabilidade!$M:$M,Contabilidade!$J:$J,$A12,Contabilidade!$X:$X,"1. Com nota fiscal recolhida") -> 3837 | D12: =SUMIFS(Contabilidade!$M:$M,Contabilidade!$J:$J,$A12,Contabilidade!$X:$X,"4. Crédito de estorno (desconto)") -> 0 | E12: =C12+D12 -> 3837 | F12: =SUMIFS(Contabilidade!$M:$M,Contabilidade!$J:$J,$A12,Contabilidade!$X:$X,"2. Abastecimento cancelado (sem nota)") -> 0 | G12: =SUMIFS(Contabilidade!$M:$M,Contabilidade!$J:$J,$A12,Contabilidade!$X:$X,"3. Sem nota fiscal") -> 0 | H12: =F12+G12 -> 0 | I12: =E12+H12 -> 3837 | J12: =IF(I$208,I12/I$208,0) -> 0.0086579389
A13: AUTO POSTO DARE | B13: =IFERROR(INDEX(Contabilidade!$K:$K,MATCH($A13,Contabilidade!$J:$J,0)),"") -> 78253424000155 | C13: =SUMIFS(Contabilidade!$M:$M,Contabilidade!$J:$J,$A13,Contabilidade!$X:$X,"1. Com nota fiscal recolhida") -> 2230.34 | D13: =SUMIFS(Contabilidade!$M:$M,Contabilidade!$J:$J,$A13,Contabilidade!$X:$X,"4. Crédito de estorno (desconto)") -> 0 | E13: =C13+D13 -> 2230.34 | F13: =SUMIFS(Contabilidade!$M:$M,Contabilidade!$J:$J,$A13,Contabilidade!$X:$X,"2. Abastecimento cancelado (sem nota)") -> 0 | G13: =SUMIFS(Contabilidade!$M:$M,Contabilidade!$J:$J,$A13,Contabilidade!$X:$X,"3. Sem nota fiscal") -> 0 | H13: =F13+G13 -> 0 | I13: =E13+H13 -> 2230.34 | J13: =IF(I$208,I13/I$208,0) -> 0.005032616
A14: AUTO POSTO DUQUE CENTENARIO | B14: =IFERROR(INDEX(Contabilidade!$K:$K,MATCH($A14,Contabilidade!$J:$J,0)),"") -> 27751075017640 | C14: =SUMIFS(Contabilidade!$M:$M,Contabilidade!$J:$J,$A14,Contabilidade!$X:$X,"1. Com nota fiscal recolhida") -> 3324.71 | D14: =SUMIFS(Contabilidade!$M:$M,Contabilidade!$J:$J,$A14,Contabilidade!$X:$X,"4. Crédito de estorno (desconto)") -> 0 | E14: =C14+D14 -> 3324.71 | F14: =SUMIFS(Contabilidade!$M:$M,Contabilidade!$J:$J,$A14,Contabilidade!$X:$X,"2. Abastecimento cancelado (sem nota)") -> 0 | G14: =SUMIFS(Contabilidade!$M:$M,Contabilidade!$J:$J,$A14,Contabilidade!$X:$X,"3. Sem nota fiscal") -> 0 | H14: =F14+G14 -> 0 | I14: =E14+H14 -> 3324.71 | J14: =IF(I$208,I14/I$208,0) -> 0.0075019901
... A207: XANXERE AV. BRASIL - FILIAL 41 - REDE TRADICAO | B207: =IFERROR(INDEX(Contabilidade!$K:$K,MATCH($A207,Contabilidade!$J:$J,0)),"") -> 37435735001391 | C207: =SUMIFS(Contabilidade!$M:$M,Contabilidade!$J:$J,$A207,Contabilidade!$X:$X,"1. Com nota fiscal recolhida") -> 277.77 | D207: =SUMIFS(Contabilidade!$M:$M,Contabilidade!$J:$J,$A207,Contabilidade!$X:$X,"4. Crédito de estorno (desconto)") -> 0 | E207: =C207+D207 -> 277.77 | F207: =SUMIFS(Contabilidade!$M:$M,Contabilidade!$J:$J,$A207,Contabilidade!$X:$X,"2. Abastecimento cancelado (sem nota)") -> 0 | G207: =SUMIFS(Contabilidade!$M:$M,Contabilidade!$J:$J,$A207,Contabilidade!$X:$X,"3. Sem nota fiscal") -> 0 | H207: =F207+G207 -> 0 | I207: =E207+H207 -> 277.77 | J207: =IF(I$208,I207/I$208,0) -> 0.00062676979
A208: TOTAL | C208: =SUM(C3:C207) -> 414653.7 | D208: =SUM(D3:D207) -> -1468.57 | E208: =SUM(E3:E207) -> 413185.13 | F208: =SUM(F3:F207) -> 331.89 | G208: =SUM(G3:G207) -> 29660.05 | H208: =SUM(H3:H207) -> 29991.94 | I208: =SUM(I3:I207) -> 443177.07 | J208: =SUM(J3:J207) -> 1
